[2023-08-08T03:49:02.525+0000] {taskinstance.py:1103} INFO - Dependencies all met for dep_context=non-requeueable deps ti=<TaskInstance: our_dag_with_python_operator_v07.greet scheduled__2022-01-07T00:00:00+00:00 [queued]>
[2023-08-08T03:49:02.533+0000] {taskinstance.py:1103} INFO - Dependencies all met for dep_context=requeueable deps ti=<TaskInstance: our_dag_with_python_operator_v07.greet scheduled__2022-01-07T00:00:00+00:00 [queued]>
[2023-08-08T03:49:02.533+0000] {taskinstance.py:1308} INFO - Starting attempt 1 of 6
[2023-08-08T03:49:02.548+0000] {taskinstance.py:1327} INFO - Executing <Task(PythonOperator): greet> on 2022-01-07 00:00:00+00:00
[2023-08-08T03:49:02.556+0000] {standard_task_runner.py:57} INFO - Started process 2027 to run task
[2023-08-08T03:49:02.562+0000] {standard_task_runner.py:84} INFO - Running: ['***', 'tasks', 'run', 'our_dag_with_python_operator_v07', 'greet', 'scheduled__2022-01-07T00:00:00+00:00', '--job-id', '327', '--raw', '--subdir', 'DAGS_FOLDER/simple_print.py', '--cfg-path', '/tmp/tmpskfoa3hv']
[2023-08-08T03:49:02.566+0000] {standard_task_runner.py:85} INFO - Job 327: Subtask greet
[2023-08-08T03:49:02.646+0000] {task_command.py:410} INFO - Running <TaskInstance: our_dag_with_python_operator_v07.greet scheduled__2022-01-07T00:00:00+00:00 [running]> on host e301933437eb
[2023-08-08T03:49:02.780+0000] {local_task_job_runner.py:115} ERROR - Received SIGTERM. Terminating subprocesses
[2023-08-08T03:49:02.846+0000] {process_utils.py:135} INFO - Sending Signals.SIGTERM to group 2027. PIDs of all processes in the group: [2027]
[2023-08-08T03:49:02.853+0000] {process_utils.py:86} INFO - Sending the signal Signals.SIGTERM to group 2027
[2023-08-08T03:49:02.854+0000] {taskinstance.py:1517} ERROR - Received SIGTERM. Terminating subprocesses.
[2023-08-08T03:49:02.903+0000] {taskinstance.py:1824} ERROR - Task failed with exception
Traceback (most recent call last):
  File "/home/airflow/.local/lib/python3.7/site-packages/airflow/models/taskinstance.py", line 1407, in _run_raw_task
    self._execute_task_with_callbacks(context, test_mode)
  File "/home/airflow/.local/lib/python3.7/site-packages/airflow/models/taskinstance.py", line 1538, in _execute_task_with_callbacks
    airflow_context_vars = context_to_airflow_vars(context, in_env_var_format=True)
  File "/home/airflow/.local/lib/python3.7/site-packages/airflow/utils/operator_helpers.py", line 80, in context_to_airflow_vars
    task = context.get("task")
  File "/usr/local/lib/python3.7/_collections_abc.py", line 660, in get
    return self[key]
  File "/home/airflow/.local/lib/python3.7/site-packages/airflow/utils/context.py", line 205, in __getitem__
    warnings.warn(_create_deprecation_warning(key, self._deprecation_replacements[key]))
  File "/home/airflow/.local/lib/python3.7/site-packages/airflow/models/taskinstance.py", line 1519, in signal_handler
    raise AirflowException("Task received SIGTERM signal")
airflow.exceptions.AirflowException: Task received SIGTERM signal
[2023-08-08T03:49:02.913+0000] {taskinstance.py:1350} INFO - Marking task as UP_FOR_RETRY. dag_id=our_dag_with_python_operator_v07, task_id=greet, execution_date=20220107T000000, start_date=20230808T034902, end_date=20230808T034902
[2023-08-08T03:49:02.969+0000] {standard_task_runner.py:109} ERROR - Failed to execute job 327 for task greet (Task received SIGTERM signal; 2027)
[2023-08-08T03:49:03.168+0000] {process_utils.py:79} INFO - Process psutil.Process(pid=2027, status='terminated', exitcode=1, started='03:49:01') (2027) terminated with exit code 1
[2023-08-08T03:49:03.176+0000] {local_task_job_runner.py:225} INFO - Task exited with return code 143
[2023-08-08T03:49:03.277+0000] {taskinstance.py:2653} INFO - 0 downstream tasks scheduled from follow-on schedule check
[2023-08-08T03:49:04.691+0000] {local_task_job_runner.py:115} ERROR - Received SIGTERM. Terminating subprocesses
