[2023-08-08T03:49:02.523+0000] {taskinstance.py:1103} INFO - Dependencies all met for dep_context=non-requeueable deps ti=<TaskInstance: our_dag_with_python_operator_v07.greet scheduled__2022-01-08T00:00:00+00:00 [queued]>
[2023-08-08T03:49:02.536+0000] {taskinstance.py:1103} INFO - Dependencies all met for dep_context=requeueable deps ti=<TaskInstance: our_dag_with_python_operator_v07.greet scheduled__2022-01-08T00:00:00+00:00 [queued]>
[2023-08-08T03:49:02.537+0000] {taskinstance.py:1308} INFO - Starting attempt 1 of 6
[2023-08-08T03:49:02.552+0000] {taskinstance.py:1327} INFO - Executing <Task(PythonOperator): greet> on 2022-01-08 00:00:00+00:00
[2023-08-08T03:49:02.562+0000] {standard_task_runner.py:57} INFO - Started process 2028 to run task
[2023-08-08T03:49:02.571+0000] {standard_task_runner.py:84} INFO - Running: ['***', 'tasks', 'run', 'our_dag_with_python_operator_v07', 'greet', 'scheduled__2022-01-08T00:00:00+00:00', '--job-id', '325', '--raw', '--subdir', 'DAGS_FOLDER/simple_print.py', '--cfg-path', '/tmp/tmpxza_es14']
[2023-08-08T03:49:02.575+0000] {standard_task_runner.py:85} INFO - Job 325: Subtask greet
[2023-08-08T03:49:02.660+0000] {task_command.py:410} INFO - Running <TaskInstance: our_dag_with_python_operator_v07.greet scheduled__2022-01-08T00:00:00+00:00 [running]> on host e301933437eb
[2023-08-08T03:49:02.779+0000] {local_task_job_runner.py:115} ERROR - Received SIGTERM. Terminating subprocesses
[2023-08-08T03:49:02.850+0000] {taskinstance.py:1547} INFO - Exporting env vars: AIRFLOW_CTX_DAG_OWNER='coder2j' AIRFLOW_CTX_DAG_ID='our_dag_with_python_operator_v07' AIRFLOW_CTX_TASK_ID='greet' AIRFLOW_CTX_EXECUTION_DATE='2022-01-08T00:00:00+00:00' AIRFLOW_CTX_TRY_NUMBER='1' AIRFLOW_CTX_DAG_RUN_ID='scheduled__2022-01-08T00:00:00+00:00'
[2023-08-08T03:49:02.852+0000] {process_utils.py:135} INFO - Sending Signals.SIGTERM to group 2028. PIDs of all processes in the group: [2028]
[2023-08-08T03:49:02.859+0000] {process_utils.py:86} INFO - Sending the signal Signals.SIGTERM to group 2028
[2023-08-08T03:49:02.860+0000] {taskinstance.py:1517} ERROR - Received SIGTERM. Terminating subprocesses.
[2023-08-08T03:49:02.944+0000] {taskinstance.py:1824} ERROR - Task failed with exception
Traceback (most recent call last):
  File "/usr/local/lib/python3.7/logging/__init__.py", line 1619, in isEnabledFor
    return self._cache[level]
KeyError: 10

During handling of the above exception, another exception occurred:

Traceback (most recent call last):
  File "/home/airflow/.local/lib/python3.7/site-packages/airflow/models/taskinstance.py", line 1407, in _run_raw_task
    self._execute_task_with_callbacks(context, test_mode)
  File "/home/airflow/.local/lib/python3.7/site-packages/airflow/models/taskinstance.py", line 1551, in _execute_task_with_callbacks
    self.task.pre_execute(context=context)
  File "/home/airflow/.local/lib/python3.7/site-packages/airflow/lineage/__init__.py", line 117, in wrapper
    self.log.debug("Preparing lineage inlets and outlets")
  File "/usr/local/lib/python3.7/logging/__init__.py", line 1365, in debug
    if self.isEnabledFor(DEBUG):
  File "/usr/local/lib/python3.7/logging/__init__.py", line 1619, in isEnabledFor
    return self._cache[level]
  File "/home/airflow/.local/lib/python3.7/site-packages/airflow/models/taskinstance.py", line 1519, in signal_handler
    raise AirflowException("Task received SIGTERM signal")
airflow.exceptions.AirflowException: Task received SIGTERM signal
[2023-08-08T03:49:02.961+0000] {taskinstance.py:1350} INFO - Marking task as UP_FOR_RETRY. dag_id=our_dag_with_python_operator_v07, task_id=greet, execution_date=20220108T000000, start_date=20230808T034902, end_date=20230808T034902
[2023-08-08T03:49:03.037+0000] {standard_task_runner.py:109} ERROR - Failed to execute job 325 for task greet (Task received SIGTERM signal; 2028)
[2023-08-08T03:49:03.085+0000] {process_utils.py:79} INFO - Process psutil.Process(pid=2028, status='terminated', exitcode=1, started='03:49:01') (2028) terminated with exit code 1
[2023-08-08T03:49:03.088+0000] {local_task_job_runner.py:225} INFO - Task exited with return code 143
[2023-08-08T03:49:03.201+0000] {taskinstance.py:2653} INFO - 0 downstream tasks scheduled from follow-on schedule check
